{
  "nbformat": 4,
  "nbformat_minor": 0,
  "metadata": {
    "colab": {
      "provenance": []
    },
    "kernelspec": {
      "name": "python3",
      "display_name": "Python 3"
    },
    "language_info": {
      "name": "python"
    }
  },
  "cells": [
    {
      "cell_type": "code",
      "execution_count": null,
      "metadata": {
        "colab": {
          "base_uri": "https://localhost:8080/"
        },
        "id": "gFPukzkLISqT",
        "outputId": "e43b2745-cc23-4cfd-dfbf-e42e43fa6cb5"
      },
      "outputs": [
        {
          "output_type": "stream",
          "name": "stdout",
          "text": [
            "Overwriting app.py\n"
          ]
        }
      ],
      "source": [
        "%%writefile app.py\n",
        "\n",
        "\n"
      ]
    },
    {
      "cell_type": "code",
      "source": [
        "! wget -q -O - ipv4.icanhazip.com"
      ],
      "metadata": {
        "colab": {
          "base_uri": "https://localhost:8080/"
        },
        "id": "qP-7g7EBIcii",
        "outputId": "74d586c8-4f54-43ab-8965-c4283ede017d"
      },
      "execution_count": null,
      "outputs": [
        {
          "output_type": "stream",
          "name": "stdout",
          "text": [
            "34.73.76.55\n"
          ]
        }
      ]
    },
    {
      "cell_type": "code",
      "source": [
        "!streamlit run /content/app.py & npx localtunnel --port 8501"
      ],
      "metadata": {
        "colab": {
          "base_uri": "https://localhost:8080/"
        },
        "id": "dk6E9JjqLuc2",
        "outputId": "76668110-97b0-4d1b-9cfa-0ed4143bc777"
      },
      "execution_count": 5,
      "outputs": [
        {
          "output_type": "stream",
          "name": "stdout",
          "text": [
            "\n",
            "Collecting usage statistics. To deactivate, set browser.gatherUsageStats to false.\n",
            "\u001b[0m\n",
            "\u001b[0m\n",
            "\u001b[34m\u001b[1m  You can now view your Streamlit app in your browser.\u001b[0m\n",
            "\u001b[0m\n",
            "\u001b[34m  Network URL: \u001b[0m\u001b[1mhttp://172.28.0.12:8501\u001b[0m\n",
            "\u001b[34m  External URL: \u001b[0m\u001b[1mhttp://34.73.76.55:8501\u001b[0m\n",
            "\u001b[0m\n",
            "\u001b[K\u001b[?25hnpx: installed 22 in 4.763s\n",
            "your url is: https://common-doodles-create.loca.lt\n",
            "2024-04-10 19:06:11.263 Uncaught app exception\n",
            "Traceback (most recent call last):\n",
            "  File \"/usr/local/lib/python3.10/dist-packages/streamlit/runtime/scriptrunner/script_runner.py\", line 584, in _run_script\n",
            "    exec(code, module.__dict__)\n",
            "  File \"/content/app.py\", line 5, in <module>\n",
            "    secrets = toml.load(\"streamlit/secrets.toml\")\n",
            "  File \"/usr/local/lib/python3.10/dist-packages/toml/decoder.py\", line 133, in load\n",
            "    with io.open(_getpath(f), encoding='utf-8') as ffile:\n",
            "FileNotFoundError: [Errno 2] No such file or directory: 'streamlit/secrets.toml'\n",
            "2024-04-10 19:08:08.075 Uncaught app exception\n",
            "Traceback (most recent call last):\n",
            "  File \"/usr/local/lib/python3.10/dist-packages/streamlit/runtime/scriptrunner/script_runner.py\", line 584, in _run_script\n",
            "    exec(code, module.__dict__)\n",
            "  File \"/content/app.py\", line 9, in <module>\n",
            "    openai.api_key = secrets[\"\"]\n",
            "KeyError: ''\n",
            "2024-04-10 19:08:34.922 Uncaught app exception\n",
            "Traceback (most recent call last):\n",
            "  File \"/usr/local/lib/python3.10/dist-packages/streamlit/runtime/scriptrunner/script_runner.py\", line 584, in _run_script\n",
            "    exec(code, module.__dict__)\n",
            "  File \"/content/app.py\", line 9, in <module>\n",
            "    openai.api_key = secrets[\"Open_api_key\"]\n",
            "KeyError: 'Open_api_key'\n",
            "2024-04-10 19:09:10.816 Uncaught app exception\n",
            "Traceback (most recent call last):\n",
            "  File \"/usr/local/lib/python3.10/dist-packages/streamlit/runtime/scriptrunner/script_runner.py\", line 584, in _run_script\n",
            "    exec(code, module.__dict__)\n",
            "  File \"/content/app.py\", line 9, in <module>\n",
            "    openai.api_key = secrets[\"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\"]\n",
            "KeyError: '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'\n",
            "2024-04-10 19:09:55.833 Uncaught app exception\n",
            "Traceback (most recent call last):\n",
            "  File \"/usr/local/lib/python3.10/dist-packages/streamlit/runtime/scriptrunner/script_runner.py\", line 584, in _run_script\n",
            "    exec(code, module.__dict__)\n",
            "  File \"/content/app.py\", line 29, in <module>\n",
            "    for response in openai.ChatCompletion.create(\n",
            "  File \"/usr/local/lib/python3.10/dist-packages/openai/api_resources/chat_completion.py\", line 25, in create\n",
            "    return super().create(*args, **kwargs)\n",
            "  File \"/usr/local/lib/python3.10/dist-packages/openai/api_resources/abstract/engine_api_resource.py\", line 153, in create\n",
            "    response, _, api_key = requestor.request(\n",
            "  File \"/usr/local/lib/python3.10/dist-packages/openai/api_requestor.py\", line 298, in request\n",
            "    resp, got_stream = self._interpret_response(result, stream)\n",
            "  File \"/usr/local/lib/python3.10/dist-packages/openai/api_requestor.py\", line 700, in _interpret_response\n",
            "    self._interpret_response_line(\n",
            "  File \"/usr/local/lib/python3.10/dist-packages/openai/api_requestor.py\", line 765, in _interpret_response_line\n",
            "    raise self.handle_error_response(\n",
            "openai.error.RateLimitError: You exceeded your current quota, please check your plan and billing details. For more information on this error, read the docs: https://platform.openai.com/docs/guides/error-codes/api-errors.\n",
            "\u001b[34m  Stopping...\u001b[0m\n",
            "^C\n"
          ]
        }
      ]
    },
    {
      "cell_type": "code",
      "source": [],
      "metadata": {
        "id": "TqlB4tNJLihq"
      },
      "execution_count": null,
      "outputs": []
    },
    {
      "cell_type": "code",
      "source": [],
      "metadata": {
        "id": "Y9jsCuGjKlTH"
      },
      "execution_count": null,
      "outputs": []
    },
    {
      "cell_type": "code",
      "source": [],
      "metadata": {
        "id": "shqGfBGsKlML"
      },
      "execution_count": null,
      "outputs": []
    },
    {
      "cell_type": "code",
      "source": [],
      "metadata": {
        "id": "8G1O9K2EKlDC"
      },
      "execution_count": null,
      "outputs": []
    },
    {
      "cell_type": "code",
      "source": [],
      "metadata": {
        "id": "k2QADxy9Kkv3"
      },
      "execution_count": null,
      "outputs": []
    }
  ]
}